<mujoco model="reacher_push">
	<compiler angle="radian" inertiafromgeom="true"/>
	<default>
		<joint armature="1" damping="1" limited="true"/>
		<geom rgba="0.7 0.7 0 1"/>
	</default>
	<option gravity="0 0 -9.81" integrator="RK4" timestep="0.04" />
	<worldbody>
		<!-- Arena -->
		<!-- <geom conaffinity="0" contype="0" name="ground" pos="0 0 0" rgba="0.9 0.9 0.9 1" size="1 1 10" type="plane"/>
		<geom conaffinity="0" fromto="-.3 -.3 .01 .3 -.3 .01" name="sideS" rgba="0.9 0.4 0.6 1" size=".02" type="capsule"/>
		<geom conaffinity="0" fromto=" .3 -.3 .01 .3  .3 .01" name="sideE" rgba="0.9 0.4 0.6 1" size=".02" type="capsule"/>
		<geom conaffinity="0" fromto="-.3  .3 .01 .3  .3 .01" name="sideN" rgba="0.9 0.4 0.6 1" size=".02" type="capsule"/>
		<geom conaffinity="0" fromto="-.3 -.3 .01 -.3 .3 .01" name="sideW" rgba="0.9 0.4 0.6 1" size=".02" type="capsule"/> -->
		<light name="light" directional="true" diffuse=".6 .6 .6" pos="0 0 1" specular=".3 .3 .3"/>
		<geom name="floor" type="plane" pos="0 0 0" size=".4 .2 10"/>
		<geom name="wall1" type="plane" pos="-.682843 0 .282843" size=".4 .2 10" zaxis="1 0 1"/>
		<geom name="wall2" type="plane" pos=".682843 0 .282843" size=".4 .2 10" zaxis="-1 0 1"/>
		<geom name="background" type="plane" pos="0 .2 .5" size="1 .5 10" zaxis="0 -1 0"/>

		<!-- Arm -->
		<!-- <geom conaffinity="0" contype="0" fromto="0 0 0.2 0 0.01 0.2" name="root" rgba="0.9 0.4 0.6 1" size=".011" type="cylinder"/> -->
		<body name="body0" pos="0 0 0.25">
			<geom fromto="0 0 0 0.2 0 0" name="link0" rgba="0.0 0.4 0.6 1" size=".02" type="capsule"/>
			<joint axis="0 -1 0" limited="false" name="joint0" pos="0 0 0" type="hinge"/>
			<body name="body1" pos="0.2 0 0">
				<joint axis="0 -1 0" limited="true" name="joint1" pos="0 0 0" range="-3.0 3.0" type="hinge"/>
				<geom fromto="0 0 0 0.2 0 0" name="link1" rgba="0.0 0.4 0.6 1" size=".02" type="capsule"/>
				<body name="fingertip" pos="0.21 0 0">
					<geom name="fingertip" pos="0 0 0" rgba="0.0 0.8 0.6 1" size=".02" type="sphere"/>
				</body>
			</body>
		</body>

		<body name="spinner" pos=".3 0 .25">
		  <joint name="hinge" frictionloss=".1" damping=".5" limited="false" axis="0 -1 0" />
		  <geom name="cap1" type="capsule" size=".04 .09"  pos=".02 0 0" rgba="0.6 0.2 0.2 1" />
		  <geom name="cap2" type="capsule" size=".04 .09"  pos="-.02 0 0" rgba="0.6 0.2 0.2 1" />
		  <site name="tip" type="sphere"  size=".02" pos="0 0 .13" />
		  <geom name="spinner_decoration" type="cylinder" fromto="0 -.045 0 0 .045 0" size=".02" />
		</body>

	</worldbody>
	<actuator>
		<motor ctrllimited="true" ctrlrange="-1.0 1.0" gear="12.0" joint="joint0"/>
		<motor ctrllimited="true" ctrlrange="-1.0 1.0" gear="12.0" joint="joint1"/>
	</actuator>
</mujoco>
